Workbook
Name SegmentaçãodeDados_UF: #N/A

Sheet dashboard

Sheet analytics
A2: Status_Pedido | B2: (Tudo) | E2: Status | F2: Contagem de Status | G2: % dos pedidos | I2: Posição | J2: Produto | K2: Lucro Médio
E3: Aprovado | F3: 134 | G3: 0.268 | I3: 1 | J3: =INDEX(E33:E45,MATCH(I3,G33:G45,0)) -> Hoodie Boxy Fit Charcoal | K3: =INDEX(F33:F45,MATCH(I3,G33:G45,0)) -> 214.9
A4: Faturamento Bruto | E4: Cancelado | F4: 38 | G4: 0.076 | I4: 2 | J4: =INDEX(E34:E46,MATCH(I4,G34:G46,0)) -> Hoodie Oversized Essential Black | K4: =INDEX(F34:F46,MATCH(I4,G34:G46,0)) -> 194.9
A5: 143767.8 | E5: Entregue | F5: 311 | G5: 0.622 | I5: 3 | J5: =INDEX(E35:E47,MATCH(I5,G35:G47,0)) -> Calça Denim Straight Fit Dark Wash | K5: =INDEX(F35:F47,MATCH(I5,G35:G47,0)) -> 189.9
E6: Inadimplente | F6: 17 | G6: 0.034 | I6: 4 | J6: =INDEX(E36:E48,MATCH(I6,G36:G48,0)) -> Moletom Crewneck ZOVY Arch | K6: =INDEX(F36:F48,MATCH(I6,G36:G48,0)) -> 177.9
A7: Status_Pedido | B7: (Vários itens) | E7: Total Geral | F7: 500 | G7: 1 | I7: 5 | J7: =INDEX(E37:E49,MATCH(I7,G37:G49,0)) -> Calça Cargo Wide Leg Black | K7: =INDEX(F37:F49,MATCH(I7,G37:G49,0)) -> 169.9
A9: Faturamento Líquido | E9: Status | F9: Contagem de Forma de Pagamento | G9: % dos pedidos totais
A10: 126965.9 | E10: Boleto Bancário | F10: 61 | G10: 0.122 | J10: Meses | K10: Lucro Mensal
E11: Cartão de Crédito | F11: 187 | G11: 0.374 | J11: abr | K11: 16108.3
A12: Status_Pedido | B12: (Tudo) | E12: Pix | F12: 252 | G12: 0.504 | J12: mai | K12: 12396.9
E13: Total Geral | F13: 500 | G13: 1 | J13: jun | K13: 16852.3
A14: Ticket Médio | J14: jul | K14: 15845.4
A15: 287.5356 | E15: Status | F15: Contagem de Status | G15: % dos pedidos | J15: ago | K15: 11926.5
E16: Aprovado | F16: 134 | G16: 0.268 | J16: set | K16: 15337.4
A17: UF | B17: Vendas | E17: Boleto Bancário | F17: 3 | G17: 0.006 | J17: out | K17: 9160
A18: BA | B18: =COUNTIF(sales!D:D,analytics!A18) -> 25 | E18: Cartão de Crédito | F18: 49 | G18: 0.098 | J18: Total Geral | K18: 97626.8
A19: DF | B19: =COUNTIF(sales!D:D,analytics!A19) -> 31 | E19: Pix | F19: 82 | G19: 0.164
A20: GO | B20: =COUNTIF(sales!D:D,analytics!A20) -> 13 | E20: Cancelado | F20: 38 | G20: 0.076
A21: MG | B21: =COUNTIF(sales!D:D,analytics!A21) -> 58 | E21: Boleto Bancário | F21: 10 | G21: 0.02
A22: PE | B22: =COUNTIF(sales!D:D,analytics!A22) -> 20 | E22: Cartão de Crédito | F22: 12 | G22: 0.024
A23: PR | B23: =COUNTIF(sales!D:D,analytics!A23) -> 38 | E23: Pix | F23: 16 | G23: 0.032
A24: RJ | B24: =COUNTIF(sales!D:D,analytics!A24) -> 68 | E24: Entregue | F24: 311 | G24: 0.622
A25: RS | B25: =COUNTIF(sales!D:D,analytics!A25) -> 41 | E25: Boleto Bancário | F25: 31 | G25: 0.062
A26: SC | B26: =COUNTIF(sales!D:D,analytics!A26) -> 29 | E26: Cartão de Crédito | F26: 126 | G26: 0.252
A27: SP | B27: =COUNTIF(sales!D:D,analytics!A27) -> 177 | E27: Pix | F27: 154 | G27: 0.308
E28: Inadimplente | F28: 17 | G28: 0.034
E29: Boleto Bancário | F29: 17 | G29: 0.034
E30: Total Geral | F30: 500 | G30: 1
E32: Produtos Disponíveis | F32: Lucro Médio | G32: Mais Lucrativos
E33: Shoulder Bag Tactical ZOVY | F33: =VLOOKUP(E33,sales!F:L,7,0)/VLOOKUP(E33,sales!F:G,2,0) -> 89.9 | G33: =_xlfn.RANK.EQ(F33,$F$33:$F$45,0) -> 11
A34: Status_Pedido | B34: (Tudo) | E34: Camiseta Oversized Minimalist White | F34: =VLOOKUP(E34,sales!F:L,7,0)/VLOOKUP(E34,sales!F:G,2,0) -> 94.9 | G34: =_xlfn.RANK.EQ(F34,$F$33:$F$45,0) -> 9
E35: Camiseta Graphic Streetwear Off-White | F35: =VLOOKUP(E35,sales!F:L,7,0)/VLOOKUP(E35,sales!F:G,2,0) -> 114.9 | G35: =_xlfn.RANK.EQ(F35,$F$33:$F$45,0) -> 7
A36: Rótulos de Linha | B36: Quantidade | C36: % dos pedidos totais | E36: Camiseta Oversized Basic Black | F36: =VLOOKUP(E36,sales!F:L,7,0)/VLOOKUP(E36,sales!F:G,2,0) -> 94.9 | G36: =_xlfn.RANK.EQ(F36,$F$33:$F$45,0) -> 9
A37: Acessórios | B37: 77 | C37: 0.1066482 | E37: Camiseta Heavyweight Urban Grey | F37: =VLOOKUP(E37,sales!F:L,7,0)/VLOOKUP(E37,sales!F:G,2,0) -> 107.9 | G37: =_xlfn.RANK.EQ(F37,$F$33:$F$45,0) -> 8
A38: Benei Beanie Streetwear Grey | B38: 17 | C38: 0.023545706 | E38: Hoodie Boxy Fit Charcoal | F38: =VLOOKUP(E38,sales!F:L,7,0)/VLOOKUP(E38,sales!F:G,2,0) -> 214.9 | G38: =_xlfn.RANK.EQ(F38,$F$33:$F$45,0) -> 1
A39: Boné Dad Hat ZOVY Black | B39: 24 | C39: 0.033240997 | E39: Calça Cargo Wide Leg Black | F39: =VLOOKUP(E39,sales!F:L,7,0)/VLOOKUP(E39,sales!F:G,2,0) -> 169.9 | G39: =_xlfn.RANK.EQ(F39,$F$33:$F$45,0) -> 5
A40: Shoulder Bag Tactical ZOVY | B40: 36 | C40: 0.049861496 | E40: Calça Sweatpants Oversized Grey | F40: =VLOOKUP(E40,sales!F:L,7,0)/VLOOKUP(E40,sales!F:G,2,0) -> 149.9 | G40: =_xlfn.RANK.EQ(F40,$F$33:$F$45,0) -> 6
A41: Calças | B41: 149 | C41: 0.20637119 | E41: Hoodie Oversized Essential Black | F41: =VLOOKUP(E41,sales!F:L,7,0)/VLOOKUP(E41,sales!F:G,2,0) -> 194.9 | G41: =_xlfn.RANK.EQ(F41,$F$33:$F$45,0) -> 2
A42: Calça Cargo Wide Leg Black | B42: 38 | C42: 0.052631579 | E42: Moletom Crewneck ZOVY Arch | F42: =VLOOKUP(E42,sales!F:L,7,0)/VLOOKUP(E42,sales!F:G,2,0) -> 177.9 | G42: =_xlfn.RANK.EQ(F42,$F$33:$F$45,0) -> 4
A43: Calça Denim Straight Fit Dark Wash | B43: 54 | C43: 0.074792244 | E43: Calça Denim Straight Fit Dark Wash | F43: =VLOOKUP(E43,sales!F:L,7,0)/VLOOKUP(E43,sales!F:G,2,0) -> 189.9 | G43: =_xlfn.RANK.EQ(F43,$F$33:$F$45,0) -> 3
...

Sheet sales
A1: ID_Pedido | B1: Data_Pedido | C1: ID_Cliente | D1: Estado | E1: Categoria | F1: Produto | G1: Quantidade | H1: Preco_Unitario | I1: Custo_Unitario | J1: Valor_Total | K1: Custo_Total | L1: Margem_Lucro | M1: Forma_Pagamento | N1: Status_Pedido
A2: ZOV-1001 | B2: 46276.169 | C2: CUST-106 | D2: RJ | E2: Acessórios | F2: Shoulder Bag Tactical ZOVY | G2: 2 | H2: 129.9 | I2: 40 | J2: 259.8 | K2: 80 | L2: 179.8 | M2: Cartão de Crédito | N2: Aprovado
A3: ZOV-1002 | B3: 46183.372 | C3: CUST-157 | D3: SP | E3: Camisetas | F3: Camiseta Oversized Minimalist White | G3: 2 | H3: 139.9 | I3: 45 | J3: 279.8 | K3: 90 | L3: 189.8 | M3: Cartão de Crédito | N3: Entregue
A4: ZOV-1003 | B4: 46301.155 | C4: CUST-273 | D4: SP | E4: Acessórios | F4: Shoulder Bag Tactical ZOVY | G4: 2 | H4: 129.9 | I4: 40 | J4: 259.8 | K4: 80 | L4: 179.8 | M4: Pix | N4: Aprovado
A5: ZOV-1004 | B5: 46252.132 | C5: CUST-251 | D5: SP | E5: Camisetas | F5: Camiseta Graphic Streetwear Off-White | G5: 1 | H5: 169.9 | I5: 55 | J5: 169.9 | K5: 55 | L5: 114.9 | M5: Pix | N5: Aprovado
A6: ZOV-1005 | B6: 46121.045 | C6: CUST-123 | D6: MG | E6: Camisetas | F6: Camiseta Oversized Minimalist White | G6: 1 | H6: 139.9 | I6: 45 | J6: 139.9 | K6: 45 | L6: 94.9 | M6: Pix | N6: Entregue
A7: ZOV-1006 | B7: 46172.767 | C7: CUST-254 | D7: RS | E7: Camisetas | F7: Camiseta Oversized Basic Black | G7: 1 | H7: 139.9 | I7: 45 | J7: 139.9 | K7: 45 | L7: 94.9 | M7: Cartão de Crédito | N7: Aprovado
A8: ZOV-1007 | B8: 46256.302 | C8: CUST-283 | D8: MG | E8: Camisetas | F8: Camiseta Graphic Streetwear Off-White | G8: 1 | H8: 169.9 | I8: 55 | J8: 169.9 | K8: 55 | L8: 114.9 | M8: Boleto Bancário | N8: Inadimplente
A9: ZOV-1008 | B9: 46169.681 | C9: CUST-250 | D9: RS | E9: Camisetas | F9: Camiseta Heavyweight Urban Grey | G9: 1 | H9: 159.9 | I9: 52 | J9: 159.9 | K9: 52 | L9: 107.9 | M9: Cartão de Crédito | N9: Entregue
A10: ZOV-1009 | B10: 46114.242 | C10: CUST-278 | D10: SP | E10: Moletons | F10: Hoodie Boxy Fit Charcoal | G10: 1 | H10: 319.9 | I10: 105 | J10: 319.9 | K10: 105 | L10: 214.9 | M10: Boleto Bancário | N10: Entregue
A11: ZOV-1010 | B11: 46200.422 | C11: CUST-139 | D11: PR | E11: Camisetas | F11: Camiseta Oversized Minimalist White | G11: 1 | H11: 139.9 | I11: 45 | J11: 139.9 | K11: 45 | L11: 94.9 | M11: Cartão de Crédito | N11: Aprovado
A12: ZOV-1011 | B12: 46308.511 | C12: CUST-126 | D12: PE | E12: Calças | F12: Calça Cargo Wide Leg Black | G12: 3 | H12: 249.9 | I12: 80 | J12: 749.7 | K12: 240 | L12: 509.7 | M12: Boleto Bancário | N12: Entregue
A13: ZOV-1012 | B13: 46210.147 | C13: CUST-191 | D13: DF | E13: Camisetas | F13: Camiseta Heavyweight Urban Grey | G13: 1 | H13: 159.9 | I13: 52 | J13: 159.9 | K13: 52 | L13: 107.9 | M13: Pix | N13: Entregue
... A501: ZOV-1500 | B501: 46241.8 | C501: CUST-207 | D501: RJ | E501: Moletons | F501: Hoodie Oversized Essential Black | G501: 2 | H501: 289.9 | I501: 95 | J501: 579.8 | K501: 190 | L501: 389.8 | M501: Boleto Bancário | N501: Entregue
